[2025-06-13T13:56:49.820+0000] {taskinstance.py:1157} INFO - Dependencies all met for dep_context=non-requeueable deps ti=<TaskInstance: ecommerce_generate_order_process.generate_order_process scheduled__2025-06-13T13:55:48.472387+00:00 [queued]>
[2025-06-13T13:56:49.829+0000] {taskinstance.py:1157} INFO - Dependencies all met for dep_context=requeueable deps ti=<TaskInstance: ecommerce_generate_order_process.generate_order_process scheduled__2025-06-13T13:55:48.472387+00:00 [queued]>
[2025-06-13T13:56:49.830+0000] {taskinstance.py:1359} INFO - Starting attempt 1 of 6
[2025-06-13T13:56:49.842+0000] {taskinstance.py:1380} INFO - Executing <Task(_PythonDecoratedOperator): generate_order_process> on 2025-06-13 13:55:48.472387+00:00
[2025-06-13T13:56:49.848+0000] {standard_task_runner.py:57} INFO - Started process 470 to run task
[2025-06-13T13:56:49.850+0000] {standard_task_runner.py:84} INFO - Running: ['***', 'tasks', 'run', 'ecommerce_generate_order_process', 'generate_order_process', 'scheduled__2025-06-13T13:55:48.472387+00:00', '--job-id', '29', '--raw', '--subdir', 'DAGS_FOLDER/generate_order_process.py', '--cfg-path', '/tmp/tmpjo9zsm4o']
[2025-06-13T13:56:49.852+0000] {standard_task_runner.py:85} INFO - Job 29: Subtask generate_order_process
[2025-06-13T13:56:49.917+0000] {task_command.py:415} INFO - Running <TaskInstance: ecommerce_generate_order_process.generate_order_process scheduled__2025-06-13T13:55:48.472387+00:00 [running]> on host f1d84043854e
[2025-06-13T13:56:50.046+0000] {taskinstance.py:1660} INFO - Exporting env vars: AIRFLOW_CTX_DAG_OWNER='***' AIRFLOW_CTX_DAG_ID='ecommerce_generate_order_process' AIRFLOW_CTX_TASK_ID='generate_order_process' AIRFLOW_CTX_EXECUTION_DATE='2025-06-13T13:55:48.472387+00:00' AIRFLOW_CTX_TRY_NUMBER='1' AIRFLOW_CTX_DAG_RUN_ID='scheduled__2025-06-13T13:55:48.472387+00:00'
[2025-06-13T13:56:50.063+0000] {logging_mixin.py:151} INFO - ----------------------------
[2025-06-13T13:56:50.063+0000] {logging_mixin.py:151} INFO - None
[2025-06-13T13:56:50.063+0000] {logging_mixin.py:151} INFO - ----------------------------
[2025-06-13T13:56:50.063+0000] {logging_mixin.py:151} INFO - None
[2025-06-13T13:56:50.077+0000] {taskinstance.py:1935} ERROR - Task failed with exception
Traceback (most recent call last):
  File "/home/airflow/.local/lib/python3.10/site-packages/airflow/decorators/base.py", line 221, in execute
    return_value = super().execute(context)
  File "/home/airflow/.local/lib/python3.10/site-packages/airflow/operators/python.py", line 192, in execute
    return_value = self.execute_callable()
  File "/home/airflow/.local/lib/python3.10/site-packages/airflow/operators/python.py", line 209, in execute_callable
    return self.python_callable(*self.op_args, **self.op_kwargs)
  File "/opt/airflow/dags/generate_order_process.py", line 26, in generate_order_process
    raise AirflowException('Order not found...')
airflow.exceptions.AirflowException: Order not found...
[2025-06-13T13:56:50.082+0000] {taskinstance.py:1398} INFO - Marking task as UP_FOR_RETRY. dag_id=ecommerce_generate_order_process, task_id=generate_order_process, execution_date=20250613T135548, start_date=20250613T135649, end_date=20250613T135650
[2025-06-13T13:56:50.092+0000] {standard_task_runner.py:104} ERROR - Failed to execute job 29 for task generate_order_process (Order not found...; 470)
[2025-06-13T13:56:50.103+0000] {local_task_job_runner.py:228} INFO - Task exited with return code 1
[2025-06-13T13:56:50.131+0000] {taskinstance.py:2776} INFO - 0 downstream tasks scheduled from follow-on schedule check
